# Generated by Django 4.2.4 on 2023-09-14 15:30

from django.conf import settings
import django.contrib.auth.models
import django.contrib.auth.validators
from django.db import migrations, models
import django.db.models.deletion


class Migration(migrations.Migration):

    dependencies = [
        ('pinigai', '0011_alter_customuser_options_family_customuser_family_and_more'),
    ]

    operations = [
        migrations.AlterModelManagers(
            name='customuser',
            managers=[
                ('objects', django.contrib.auth.models.UserManager()),
            ],
        ),
        migrations.AddField(
            model_name='family',
            name='parent_family',
            field=models.ForeignKey(blank=True, null=True, on_delete=django.db.models.deletion.SET_NULL, related_name='child_families', to='pinigai.family'),
        ),
        migrations.AlterField(
            model_name='customuser',
            name='email',
            field=models.EmailField(max_length=254, unique=True),
        ),
        migrations.AlterField(
            model_name='customuser',
            name='family',
            field=models.ForeignKey(blank=True, null=True, on_delete=django.db.models.deletion.SET_NULL, related_name='family_members', to='pinigai.family'),
        ),
        migrations.AlterField(
            model_name='customuser',
            name='username',
            field=models.CharField(error_messages={'unique': 'A user with that username already exists.'}, help_text='Required. 150 characters or fewer. Letters, digits and @/./+/-/_ only.', max_length=150, unique=True, validators=[django.contrib.auth.validators.UnicodeUsernameValidator()], verbose_name='username'),
        ),
        migrations.AlterField(
            model_name='family',
            name='members',
            field=models.ManyToManyField(blank=True, related_name='families', to=settings.AUTH_USER_MODEL),
        ),
    ]
